<?xml version="1.0" ?> <!-- =================================================================================== --> <!-- |    This document was autogenerated by xacro from /root/colcon_ws/install/abb_irb_120_resource/share/abb_irb_120_resource/urdf/irb_120_dual.urdf.xacro | --> <!-- |    EDITING THIS FILE BY HAND IS NOT RECOMMENDED                                 | --> <!-- =================================================================================== --> <robot name="abb"> 
<material name="white"> 
<color rgba="1 1 1 1"/> 
</material> 
<link name="base_link"/> 
<!-- <link name="base_link"/> --> 
<link name="r1_link_0"> 
<visual> 
<geometry> 
<mesh filename="package://abb_irb_120_resource/meshes/Link_1.stl"/> 
</geometry> 
<material name="white"/> 
</visual> 
<collision> 
<geometry> 
<mesh filename="package://abb_irb_120_resource/meshes/Link_1.stl"/> 
</geometry> 
</collision> 
</link> 
<joint name="r1_joint_0" type="fixed"> 
<parent link="base_link"/> 
<child link="r1_link_0"/> 
<axis xyz="0 0 1"/> 
<origin rpy="0.0 0.0 0.78539" xyz="0.0 -0.5 0.0"/> 
</joint>
 <link name="r1_link_1"> <visual> <geometry> <mesh filename="package://abb_irb_120_resource/meshes/Link_2.stl"/> </geometry> <material name="white"/> </visual> <collision> <geometry> <mesh filename="package://abb_irb_120_resource/meshes/Link_2.stl"/> </geometry> </collision> </link> <joint name="r1_joint_1" type="revolute"> <parent link="r1_link_0"/> <child link="r1_link_1"/> <axis xyz="0 0 1"/> <origin rpy="0.0 0.0 0.0" xyz="0.0 0.0 0.166"/> <limit effort="1000.0" lower="-2.87925" upper="2.87925" velocity="1000"/> </joint> <link name="r1_link_2"> <visual> <geometry> <mesh filename="package://abb_irb_120_resource/meshes/Link_3.stl"/> </geometry> <material name="white"/> </visual> <collision> <geometry> <mesh filename="package://abb_irb_120_resource/meshes/Link_3.stl"/> </geometry> </collision> </link> <joint name="r1_joint_2" type="revolute"> <parent link="r1_link_1"/> <child link="r1_link_2"/> <axis xyz="0 0 1"/> <origin rpy="-1.5707 0.0 0.0" xyz="0.0 0.0 0.124"/> <limit effort="1000.0" lower="-1.9195" upper="1.9195" velocity="1000"/> </joint> <link name="r1_link_3"> <visual> <geometry> <mesh filename="package://abb_irb_120_resource/meshes/Link_4.stl"/> </geometry> <material name="white"/> </visual> <collision> <geometry> <mesh filename="package://abb_irb_120_resource/meshes/Link_4.stl"/> </geometry> </collision> </link> <joint name="r1_joint_3" type="revolute"> <parent link="r1_link_2"/> <child link="r1_link_3"/> <axis xyz="0 0 1"/> <origin rpy="0.0 0.0 -1.5707" xyz="0.0 -0.270 0.0"/> <limit effort="1000.0" lower="-1.9195" upper="1.2215" velocity="1000"/> </joint> <link name="r1_link_4"> <visual> <geometry> <mesh filename="package://abb_irb_120_resource/meshes/Link_5.stl"/> </geometry> <material name="white"/> </visual> <collision> <geometry> <mesh filename="package://abb_irb_120_resource/meshes/Link_5.stl"/> </geometry> </collision> </link> <joint name="r1_joint_4" type="revolute"> <parent link="r1_link_3"/> <child link="r1_link_4"/> <axis xyz="0 0 1"/> <origin rpy="-1.5707 0.0 0.0" xyz="0.07 0.149 0.0"/> <limit effort="1000.0" lower="-2.792" upper="2.792" velocity="1000"/> </joint> <link name="r1_link_5"> <visual> <geometry> <mesh filename="package://abb_irb_120_resource/meshes/Link_6.stl"/> </geometry> <material name="white"/> </visual> <collision> <geometry> <mesh filename="package://abb_irb_120_resource/meshes/Link_6.stl"/> </geometry> </collision> </link> <joint name="r1_joint_5" type="revolute"> <parent link="r1_link_4"/> <child link="r1_link_5"/> <axis xyz="0 0 1"/> <origin rpy="1.5707 0.0 0.0" xyz="0.0 0.0 0.1524"/> <limit effort="1000.0" lower="-2.0940000000000003" upper="2.0940000000000003" velocity="1000"/> </joint> <link name="r1_link_6"> <visual> <geometry> <mesh filename="package://abb_irb_120_resource/meshes/Link_7.stl"/> </geometry> <material name="white"/> </visual> <collision> <geometry> <mesh filename="package://abb_irb_120_resource/meshes/Link_7.stl"/> </geometry> </collision> </link> <joint name="r1_joint_6" type="revolute"> <parent link="r1_link_5"/> <child link="r1_link_6"/> <axis xyz="0 0 1"/> <origin rpy="-1.5707 0.0 0.0" xyz="0.0 0.06041 0.0"/> <limit effort="1000.0" lower="-6.98" upper="6.98" velocity="1000"/> </joint> <link name="r1_endeffector"/> <joint name="r1_joint_endeffector" type="fixed"> <parent link="r1_link_6"/> <child link="r1_endeffector"/> <origin rpy="0.0 0.0 0.0" xyz="0.0 0.0 0.012"/> </joint> <!-- <link name="base_link"/> --> <link name="r2_link_0"> <visual> <geometry> <mesh filename="package://abb_irb_120_resource/meshes/Link_1.stl"/> </geometry> <material name="white"/> </visual> <collision> <geometry> <mesh filename="package://abb_irb_120_resource/meshes/Link_1.stl"/> </geometry> </collision> </link> <joint name="r2_joint_0" type="fixed"> <parent link="base_link"/> <child link="r2_link_0"/> <axis xyz="0 0 1"/> <origin rpy="0.0 0.0 -0.78539" xyz="0.0 0.5 0.0"/> </joint> <link name="r2_link_1"> <visual> <geometry> <mesh filename="package://abb_irb_120_resource/meshes/Link_2.stl"/> </geometry> <material name="white"/> </visual> <collision> <geometry> <mesh filename="package://abb_irb_120_resource/meshes/Link_2.stl"/> </geometry> </collision> </link> <joint name="r2_joint_1" type="revolute"> <parent link="r2_link_0"/> <child link="r2_link_1"/> <axis xyz="0 0 1"/> <origin rpy="0.0 0.0 0.0" xyz="0.0 0.0 0.166"/> <limit effort="1000.0" lower="-2.87925" upper="2.87925" velocity="1000"/> </joint> <link name="r2_link_2"> <visual> <geometry> <mesh filename="package://abb_irb_120_resource/meshes/Link_3.stl"/> </geometry> <material name="white"/> </visual> <collision> <geometry> <mesh filename="package://abb_irb_120_resource/meshes/Link_3.stl"/> </geometry> </collision> </link> <joint name="r2_joint_2" type="revolute"> <parent link="r2_link_1"/> <child link="r2_link_2"/> <axis xyz="0 0 1"/> <origin rpy="-1.5707 0.0 0.0" xyz="0.0 0.0 0.124"/> <limit effort="1000.0" lower="-1.9195" upper="1.9195" velocity="1000"/> </joint> <link name="r2_link_3"> <visual> <geometry> <mesh filename="package://abb_irb_120_resource/meshes/Link_4.stl"/> </geometry> <material name="white"/> </visual> <collision> <geometry> <mesh filename="package://abb_irb_120_resource/meshes/Link_4.stl"/> </geometry> </collision> </link> <joint name="r2_joint_3" type="revolute"> <parent link="r2_link_2"/> <child link="r2_link_3"/> <axis xyz="0 0 1"/> <origin rpy="0.0 0.0 -1.5707" xyz="0.0 -0.270 0.0"/> <limit effort="1000.0" lower="-1.9195" upper="1.2215" velocity="1000"/> </joint> <link name="r2_link_4"> <visual> <geometry> <mesh filename="package://abb_irb_120_resource/meshes/Link_5.stl"/> </geometry> <material name="white"/> </visual> <collision> <geometry> <mesh filename="package://abb_irb_120_resource/meshes/Link_5.stl"/> </geometry> </collision> </link> <joint name="r2_joint_4" type="revolute"> <parent link="r2_link_3"/> <child link="r2_link_4"/> <axis xyz="0 0 1"/> <origin rpy="-1.5707 0.0 0.0" xyz="0.07 0.149 0.0"/> <limit effort="1000.0" lower="-2.792" upper="2.792" velocity="1000"/> </joint> <link name="r2_link_5"> <visual> <geometry> <mesh filename="package://abb_irb_120_resource/meshes/Link_6.stl"/> </geometry> <material name="white"/> </visual> <collision> <geometry> <mesh filename="package://abb_irb_120_resource/meshes/Link_6.stl"/> </geometry> </collision> </link> <joint name="r2_joint_5" type="revolute"> <parent link="r2_link_4"/> <child link="r2_link_5"/> <axis xyz="0 0 1"/> <origin rpy="1.5707 0.0 0.0" xyz="0.0 0.0 0.1524"/> <limit effort="1000.0" lower="-2.0940000000000003" upper="2.0940000000000003" velocity="1000"/> </joint> <link name="r2_link_6"> <visual> <geometry> <mesh filename="package://abb_irb_120_resource/meshes/Link_7.stl"/> </geometry> <material name="white"/> </visual> <collision> <geometry> <mesh filename="package://abb_irb_120_resource/meshes/Link_7.stl"/> </geometry> </collision> </link> <joint name="r2_joint_6" type="revolute"> <parent link="r2_link_5"/> <child link="r2_link_6"/> <axis xyz="0 0 1"/> <origin rpy="-1.5707 0.0 0.0" xyz="0.0 0.06041 0.0"/> <limit effort="1000.0" lower="-6.98" upper="6.98" velocity="1000"/> </joint> <link name="r2_endeffector"/> <joint name="r2_joint_endeffector" type="fixed"> <parent link="r2_link_6"/> <child link="r2_endeffector"/> <origin rpy="0.0 0.0 0.0" xyz="0.0 0.0 0.012"/> </joint> <ros2_control name="r1_ABBMultiInterfaceHardware" type="system"> <hardware> <plugin>abb_hardware_interface/ABBSystemHardware</plugin> <param name="rws_port">80</param> <param name="rws_ip">192.168.88.190</param> <param name="prefix">r1</param> <param name="egm_port">6511</param> </hardware> <joint name="r1_joint_1"> <command_interface name="position"> <param name="min">{-2*pi}</param> <param name="max">{2*pi}</param> </command_interface> <command_interface name="velocity"/> <state_interface name="position"> <param name="initial_value">0.0</param> </state_interface> <state_interface name="velocity"/> </joint> <joint name="r1_joint_2"> <command_interface name="position"> <param name="min">-2.41</param> <param name="max">2.41</param> </command_interface> <command_interface name="velocity"/> <state_interface name="position"> <param name="initial_value">0.0</param> </state_interface> <state_interface name="velocity"/> </joint> <joint name="r1_joint_3"> <command_interface name="position"> <param name="min">{-2*pi}</param> <param name="max">{2*pi}</param> </command_interface> <command_interface name="velocity"/> <state_interface name="position"> <param name="initial_value">0.0</param> </state_interface> <state_interface name="velocity"/> </joint> <joint name="r1_joint_4"> <command_interface name="position"> <param name="min">-2.66</param> <param name="max">2.66</param> </command_interface> <command_interface name="velocity"/> <state_interface name="position"> <param name="initial_value">0.0</param> </state_interface> <state_interface name="velocity"/> </joint> <joint name="r1_joint_5"> <command_interface name="position"> <param name="min">{-2*pi}</param> <param name="max">{2*pi}</param> </command_interface> <command_interface name="velocity"/> <state_interface name="position"> <param name="initial_value">0.0</param> </state_interface> <state_interface name="velocity"/> </joint> <joint name="r1_joint_6"> <command_interface name="position"> <param name="min">-2.23</param> <param name="max">2.23</param> </command_interface> <command_interface name="velocity"/> <state_interface name="position"> <param name="initial_value">0.0</param> </state_interface> <state_interface name="velocity"/> </joint> </ros2_control> <ros2_control name="r2_ABBMultiInterfaceHardware" type="system"> <hardware> <plugin>abb_hardware_interface/ABBSystemHardware</plugin> <param name="rws_port">80</param> <param name="rws_ip">192.168.88.200</param> <param name="prefix">r2</param> <param name="egm_port">6512</param> </hardware> <joint name="r2_joint_1"> <command_interface name="position"> <param name="min">{-2*pi}</param> <param name="max">{2*pi}</param> </command_interface> <command_interface name="velocity"/> <state_interface name="position"> <param name="initial_value">0.0</param> </state_interface> <state_interface name="velocity"/> </joint> <joint name="r2_joint_2"> <command_interface name="position"> <param name="min">-2.41</param> <param name="max">2.41</param> </command_interface> <command_interface name="velocity"/> <state_interface name="position"> <param name="initial_value">0.0</param> </state_interface> <state_interface name="velocity"/> </joint> <joint name="r2_joint_3"> <command_interface name="position"> <param name="min">{-2*pi}</param> <param name="max">{2*pi}</param> </command_interface> <command_interface name="velocity"/> <state_interface name="position"> <param name="initial_value">0.0</param> </state_interface> <state_interface name="velocity"/> </joint> <joint name="r2_joint_4"> <command_interface name="position"> <param name="min">-2.66</param> <param name="max">2.66</param> </command_interface> <command_interface name="velocity"/> <state_interface name="position"> <param name="initial_value">0.0</param> </state_interface> <state_interface name="velocity"/> </joint> <joint name="r2_joint_5"> <command_interface name="position"> <param name="min">{-2*pi}</param> <param name="max">{2*pi}</param> </command_interface> <command_interface name="velocity"/> <state_interface name="position"> <param name="initial_value">0.0</param> </state_interface> <state_interface name="velocity"/> </joint> <joint name="r2_joint_6"> <command_interface name="position"> <param name="min">-2.23</param> <param name="max">2.23</param> </command_interface> <command_interface name="velocity"/> <state_interface name="position"> <param name="initial_value">0.0</param> </state_interface> <state_interface name="velocity"/> </joint> </ros2_control> </robot>
